Workbook

Sheet Order Accepted
A1: MMYYYY | B1: Product | C1: Value | E1: Product | F1: Product A
A2: 46048 | B2: Product A | C2: 1250000
A3: 46048 | B3: Product B | C3: 980000 | F3: Product A
A4: 46048 | B4: Product C | C4: 1450000 | F4: Jan | G4: Feb | H4: Mar | I4: Apr | J4: May | K4: Jun | L4: Jul | M4: Aug | N4: Grand Total
A5: 46079 | B5: Product A | C5: 1320000 | E5: Total | F5: 1250000 | G5: 1320000 | H5: 1410000 | I5: 1500000 | J5: 1430000 | K5: 1600000 | L5: 1540000 | M5: 1680000 | N5: 11730000
A6: 46079 | B6: Product B | C6: 1080000
A7: 46079 | B7: Product C | C7: 1580000
A8: 46107 | B8: Product A | C8: 1410000 | E8: Product | F8: Product B
A9: 46107 | B9: Product B | C9: 1160000
A10: 46107 | B10: Product C | C10: 1720000 | F10: Product B
A11: 46138 | B11: Product A | C11: 1500000 | F11: Jan | G11: Feb | H11: Mar | I11: Apr | J11: May | K11: Jun | L11: Jul | M11: Aug | N11: Grand Total
A12: 46138 | B12: Product B | C12: 1210000 | E12: Total | F12: 980000 | G12: 1080000 | H12: 1160000 | I12: 1210000 | J12: 1170000 | K12: 1280000 | L12: 1240000 | M12: 1350000 | N12: 9470000
A13: 46138 | B13: Product C | C13: 1810000
A14: 46168 | B14: Product A | C14: 1430000
A15: 46168 | B15: Product B | C15: 1170000 | E15: Product | F15: Product C
A16: 46168 | B16: Product C | C16: 1690000
A17: 46199 | B17: Product A | C17: 1600000 | F17: Product C
A18: 46199 | B18: Product B | C18: 1280000 | F18: Jan | G18: Feb | H18: Mar | I18: Apr | J18: May | K18: Jun | L18: Jul | M18: Aug | N18: Grand Total
A19: 46199 | B19: Product C | C19: 1910000 | E19: Total | F19: 1450000 | G19: 1580000 | H19: 1720000 | I19: 1810000 | J19: 1690000 | K19: 1910000 | L19: 1840000 | M19: 1980000 | N19: 13980000
A20: 46229 | B20: Product A | C20: 1540000
A21: 46229 | B21: Product B | C21: 1240000
A22: 46229 | B22: Product C | C22: 1840000 | E22: Product | F22: (All)
A23: 46260 | B23: Product A | C23: 1680000
A24: 46260 | B24: Product B | C24: 1350000 | F24: All Product
A25: 46260 | B25: Product C | C25: 1980000 | F25: Jan | G25: Feb | H25: Mar | I25: Apr | J25: May | K25: Jun | L25: Jul | M25: Aug | N25: Grand Total
E26: Total | F26: 3680000 | G26: 3980000 | H26: 4290000 | I26: 4520000 | J26: 4290000 | K26: 4790000 | L26: 4620000 | M26: 5010000 | N26: 35180000

Sheet OA_Target
A1: MMYYYY | B1: Product | C1: Value | E1: Product | F1: Product A
A2: 46048 | B2: Product A | C2: 1000000
A3: 46048 | B3: Product B | C3: 950000 | F3: Product A
A4: 46048 | B4: Product C | C4: 1400000 | F4: Jan | G4: Feb | H4: Mar | I4: Apr | J4: May | K4: Jun | L4: Jul | M4: Aug | N4: Grand Total
A5: 46079 | B5: Product A | C5: 1620000 | E5: Total | F5: 1000000 | G5: 1620000 | H5: 1510000 | I5: 1800000 | J5: 1600000 | K5: 1600000 | L5: 1800000 | M5: 1600000 | N5: 12530000
A6: 46079 | B6: Product B | C6: 1400000
A7: 46079 | B7: Product C | C7: 1700000
A8: 46107 | B8: Product A | C8: 1510000 | E8: Product | F8: Product B
A9: 46107 | B9: Product B | C9: 1350000
A10: 46107 | B10: Product C | C10: 1900000 | F10: Product B
A11: 46138 | B11: Product A | C11: 1800000 | F11: Jan | G11: Feb | H11: Mar | I11: Apr | J11: May | K11: Jun | L11: Jul | M11: Aug | N11: Grand Total
A12: 46138 | B12: Product B | C12: 1700000 | E12: Total | F12: 950000 | G12: 1400000 | H12: 1350000 | I12: 1700000 | J12: 1300000 | K12: 1500000 | L12: 1400000 | M12: 1300000 | N12: 10900000
A13: 46138 | B13: Product C | C13: 1800000
A14: 46168 | B14: Product A | C14: 1600000
A15: 46168 | B15: Product B | C15: 1300000 | E15: Product | F15: Product C
A16: 46168 | B16: Product C | C16: 1800000
A17: 46199 | B17: Product A | C17: 1600000 | F17: Product C
A18: 46199 | B18: Product B | C18: 1500000 | F18: Jan | G18: Feb | H18: Mar | I18: Apr | J18: May | K18: Jun | L18: Jul | M18: Aug | N18: Grand Total
A19: 46199 | B19: Product C | C19: 2000000 | E19: Total | F19: 1400000 | G19: 1700000 | H19: 1900000 | I19: 1800000 | J19: 1800000 | K19: 2000000 | L19: 2000000 | M19: 2000000 | N19: 14600000
A20: 46229 | B20: Product A | C20: 1800000
A21: 46229 | B21: Product B | C21: 1400000
A22: 46229 | B22: Product C | C22: 2000000 | E22: Product | F22: (All)
A23: 46260 | B23: Product A | C23: 1600000
A24: 46260 | B24: Product B | C24: 1300000 | F24: All Product
A25: 46260 | B25: Product C | C25: 2000000 | F25: Jan | G25: Feb | H25: Mar | I25: Apr | J25: May | K25: Jun | L25: Jul | M25: Aug | N25: Grand Total
E26: Total | F26: 3350000 | G26: 4720000 | H26: 4760000 | I26: 5300000 | J26: 4700000 | K26: 5100000 | L26: 5200000 | M26: 4900000 | N26: 38030000

Sheet Order Delivered
A1: MMYYYY | B1: Product | C1: Value | E1: Product | F1: Product A
A2: 46048 | B2: Product A | C2: 1138000
A3: 46048 | B3: Product B | C3: 911000 | F3: Column Labels
A4: 46048 | B4: Product C | C4: 1305000 | F4: Jan | G4: Feb | H4: Mar | I4: Apr | J4: May | K4: Jun | L4: Jul | M4: Aug | N4: Grand Total
A5: 46079 | B5: Product A | C5: 1214000 | E5: Total | F5: 1138000 | G5: 1214000 | H5: 1311000 | I5: 1425000 | J5: 1316000 | K5: 1504000 | L5: 1432000 | M5: 1596000 | N5: 10936000
A6: 46079 | B6: Product B | C6: 1015000
A7: 46079 | B7: Product C | C7: 1438000
A8: 46107 | B8: Product A | C8: 1311000 | E8: Product | F8: Product B
A9: 46107 | B9: Product B | C9: 1067000
A10: 46107 | B10: Product C | C10: 1617000 | F10: Column Labels
A11: 46138 | B11: Product A | C11: 1425000 | F11: Jan | G11: Feb | H11: Mar | I11: Apr | J11: May | K11: Jun | L11: Jul | M11: Aug | N11: Grand Total
A12: 46138 | B12: Product B | C12: 1125000 | E12: Total | F12: 911000 | G12: 1015000 | H12: 1067000 | I12: 1125000 | J12: 1112000 | K12: 1178000 | L12: 1166000 | M12: 1256000 | N12: 8830000
A13: 46138 | B13: Product C | C13: 1665000
A14: 46168 | B14: Product A | C14: 1316000
A15: 46168 | B15: Product B | C15: 1112000 | E15: Product | F15: Product C
A16: 46168 | B16: Product C | C16: 1572000
A17: 46199 | B17: Product A | C17: 1504000 | F17: Column Labels
A18: 46199 | B18: Product B | C18: 1178000 | F18: Jan | G18: Feb | H18: Mar | I18: Apr | J18: May | K18: Jun | L18: Jul | M18: Aug | N18: Grand Total
A19: 46199 | B19: Product C | C19: 1814000 | E19: Total | F19: 1305000 | G19: 1438000 | H19: 1617000 | I19: 1665000 | J19: 1572000 | K19: 1814000 | L19: 1693000 | M19: 1861000 | N19: 12965000
A20: 46229 | B20: Product A | C20: 1432000
A21: 46229 | B21: Product B | C21: 1166000
A22: 46229 | B22: Product C | C22: 1693000 | E22: Product | F22: (All)
A23: 46260 | B23: Product A | C23: 1596000
A24: 46260 | B24: Product B | C24: 1256000 | F24: Column Labels
A25: 46260 | B25: Product C | C25: 1861000 | F25: Jan | G25: Feb | H25: Mar | I25: Apr | J25: May | K25: Jun | L25: Jul | M25: Aug | N25: Grand Total
E26: Total | F26: 3354000 | G26: 3667000 | H26: 3995000 | I26: 4215000 | J26: 4000000 | K26: 4496000 | L26: 4291000 | M26: 4713000 | N26: 32731000

Sheet OD_Target
A1: MMYYYY | B1: Product | C1: Value | E1: Product | F1: Product A
A2: 46048 | B2: Product A | C2: 1200000
A3: 46048 | B3: Product B | C3: 1000000 | F3: Column Labels
A4: 46048 | B4: Product C | C4: 1300000 | F4: Jan | G4: Feb | H4: Mar | I4: Apr | J4: May | K4: Jun | L4: Jul | M4: Aug | N4: Grand Total
A5: 46079 | B5: Product A | C5: 1300000 | E5: Total | F5: 1200000 | G5: 1300000 | H5: 1300000 | I5: 1500000 | J5: 1300000 | K5: 1600000 | L5: 1800000 | M5: 1600000 | N5: 11600000
A6: 46079 | B6: Product B | C6: 1200000
A7: 46079 | B7: Product C | C7: 1400000
A8: 46107 | B8: Product A | C8: 1300000 | E8: Product | F8: Product B
A9: 46107 | B9: Product B | C9: 1100000
A10: 46107 | B10: Product C | C10: 1600000 | F10: Column Labels
A11: 46138 | B11: Product A | C11: 1500000 | F11: Jan | G11: Feb | H11: Mar | I11: Apr | J11: May | K11: Jun | L11: Jul | M11: Aug | N11: Grand Total
A12: 46138 | B12: Product B | C12: 1200000 | E12: Total | F12: 1000000 | G12: 1200000 | H12: 1100000 | I12: 1200000 | J12: 1200000 | K12: 1200000 | L12: 1200000 | M12: 1200000 | N12: 9300000
A13: 46138 | B13: Product C | C13: 1600000
A14: 46168 | B14: Product A | C14: 1300000
A15: 46168 | B15: Product B | C15: 1200000 | E15: Product | F15: Product C
A16: 46168 | B16: Product C | C16: 1500000
A17: 46199 | B17: Product A | C17: 1600000 | F17: Column Labels
A18: 46199 | B18: Product B | C18: 1200000 | F18: Jan | G18: Feb | H18: Mar | I18: Apr | J18: May | K18: Jun | L18: Jul | M18: Aug | N18: Grand Total
A19: 46199 | B19: Product C | C19: 2000000 | E19: Total | F19: 1300000 | G19: 1400000 | H19: 1600000 | I19: 1600000 | J19: 1500000 | K19: 2000000 | L19: 1800000 | M19: 1800000 | N19: 13000000
A20: 46229 | B20: Product A | C20: 1800000
A21: 46229 | B21: Product B | C21: 1200000
A22: 46229 | B22: Product C | C22: 1800000 | E22: Product | F22: (All)
A23: 46260 | B23: Product A | C23: 1600000
A24: 46260 | B24: Product B | C24: 1200000 | F24: Column Labels
A25: 46260 | B25: Product C | C25: 1800000 | F25: Jan | G25: Feb | H25: Mar | I25: Apr | J25: May | K25: Jun | L25: Jul | M25: Aug | N25: Grand Total
E26: Total | F26: 3500000 | G26: 3900000 | H26: 4000000 | I26: 4300000 | J26: 4000000 | K26: 4800000 | L26: 4800000 | M26: 4600000 | N26: 33900000

Sheet Churn
A1: MMYYYY | B1: Product | C1: Value | E1: Product | F1: Product A
A2: 46048 | B2: Product A | C2: 104000
A3: 46048 | B3: Product B | C3: 206000 | F3: All Product
A4: 46048 | B4: Product C | C4: 116000 | F4: Jan | G4: Feb | H4: Mar | I4: Apr | J4: May | K4: Jun | L4: Jul | M4: Aug | N4: Grand Total
A5: 46079 | B5: Product A | C5: 102000 | E5: Total | F5: 104000 | G5: 102000 | H5: 128000 | I5: 90000 | J5: 114000 | K5: 104000 | L5: 108000 | M5: 192000 | N5: 942000
A6: 46079 | B6: Product B | C6: 210000
A7: 46079 | B7: Product C | C7: 118000
A8: 46107 | B8: Product A | C8: 128000 | E8: Product | F8: Product B
A9: 46107 | B9: Product B | C9: 281000
A10: 46107 | B10: Product C | C10: 195000 | F10: Product A
A11: 46138 | B11: Product A | C11: 90000 | F11: Jan | G11: Feb | H11: Mar | I11: Apr | J11: May | K11: Jun | L11: Jul | M11: Aug | N11: Grand Total
A12: 46138 | B12: Product B | C12: 179000 | E12: Total | F12: 206000 | G12: 210000 | H12: 281000 | I12: 179000 | J12: 364000 | K12: 196000 | L12: 174000 | M12: 195000 | N12: 1805000
A13: 46138 | B13: Product C | C13: 327000
A14: 46168 | B14: Product A | C14: 114000
A15: 46168 | B15: Product B | C15: 364000 | E15: Product | F15: Product C
A16: 46168 | B16: Product C | C16: 410000
A17: 46199 | B17: Product A | C17: 104000 | F17: Product B
A18: 46199 | B18: Product B | C18: 196000 | F18: Jan | G18: Feb | H18: Mar | I18: Apr | J18: May | K18: Jun | L18: Jul | M18: Aug | N18: Grand Total
A19: 46199 | B19: Product C | C19: 215000 | E19: Total | F19: 116000 | G19: 118000 | H19: 195000 | I19: 327000 | J19: 410000 | K19: 215000 | L19: 138000 | M19: 319000 | N19: 1838000
A20: 46229 | B20: Product A | C20: 108000
A21: 46229 | B21: Product B | C21: 174000
A22: 46229 | B22: Product C | C22: 138000 | E22: Product | F22: (All)
A23: 46260 | B23: Product A | C23: 192000
A24: 46260 | B24: Product B | C24: 195000 | F24: Product C
A25: 46260 | B25: Product C | C25: 319000 | F25: Jan | G25: Feb | H25: Mar | I25: Apr | J25: May | K25: Jun | L25: Jul | M25: Aug | N25: Grand Total
E26: Total | F26: 426000 | G26: 430000 | H26: 604000 | I26: 596000 | J26: 888000 | K26: 515000 | L26: 420000 | M26: 706000 | N26: 4585000

Sheet Churn_Target
A1: MMYYYY | B1: Product | C1: Value | E1: Product | F1: Product A
A2: 46048 | B2: Product A | C2: 100000
A3: 46048 | B3: Product B | C3: 200000 | F3: All Product
A4: 46048 | B4: Product C | C4: 100000 | F4: Jan | G4: Feb | H4: Mar | I4: Apr | J4: May | K4: Jun | L4: Jul | M4: Aug | N4: Grand Total
A5: 46079 | B5: Product A | C5: 100000 | E5: Total | F5: 100000 | G5: 100000 | H5: 120000 | I5: 100000 | J5: 150000 | K5: 150000 | L5: 150000 | M5: 200000 | N5: 1070000
A6: 46079 | B6: Product B | C6: 200000
A7: 46079 | B7: Product C | C7: 100000
A8: 46107 | B8: Product A | C8: 120000 | E8: Product | F8: Product B
A9: 46107 | B9: Product B | C9: 280000
A10: 46107 | B10: Product C | C10: 200000 | F10: Product A
A11: 46138 | B11: Product A | C11: 100000 | F11: Jan | G11: Feb | H11: Mar | I11: Apr | J11: May | K11: Jun | L11: Jul | M11: Aug | N11: Grand Total
A12: 46138 | B12: Product B | C12: 180000 | E12: Total | F12: 200000 | G12: 200000 | H12: 280000 | I12: 180000 | J12: 200000 | K12: 150000 | L12: 200000 | M12: 200000 | N12: 1610000
A13: 46138 | B13: Product C | C13: 200000
A14: 46168 | B14: Product A | C14: 150000
A15: 46168 | B15: Product B | C15: 200000 | E15: Product | F15: Product C
A16: 46168 | B16: Product C | C16: 200000
A17: 46199 | B17: Product A | C17: 150000 | F17: Product B
A18: 46199 | B18: Product B | C18: 150000 | F18: Jan | G18: Feb | H18: Mar | I18: Apr | J18: May | K18: Jun | L18: Jul | M18: Aug | N18: Grand Total
A19: 46199 | B19: Product C | C19: 200000 | E19: Total | F19: 100000 | G19: 100000 | H19: 200000 | I19: 200000 | J19: 200000 | K19: 200000 | L19: 150000 | M19: 200000 | N19: 1350000
A20: 46229 | B20: Product A | C20: 150000
A21: 46229 | B21: Product B | C21: 200000
A22: 46229 | B22: Product C | C22: 150000 | E22: Product | F22: (All)
A23: 46260 | B23: Product A | C23: 200000
A24: 46260 | B24: Product B | C24: 200000 | F24: Product C
A25: 46260 | B25: Product C | C25: 200000 | F25: Jan | G25: Feb | H25: Mar | I25: Apr | J25: May | K25: Jun | L25: Jul | M25: Aug | N25: Grand Total
E26: Total | F26: 400000 | G26: 400000 | H26: 600000 | I26: 480000 | J26: 550000 | K26: 500000 | L26: 500000 | M26: 600000 | N26: 4030000

Sheet Checking
B1: 1 | C1: 2 | D1: 3 | E1: 4 | F1: 5 | G1: 6 | H1: 7 | I1: 8 | J1: 9 | K1: 10 | L1: 11 | M1: 12 | O1: 1 | P1: 2 | Q1: 3 | R1: 4 | S1: 5 | T1: 6 | U1: 7 | V1: 8 | W1: 9 | X1: 10 | Y1: 11 | Z1: 12
B2: =SUM(Details!C$6:$C$6)/SUM(Details!O$6:$O$6) -> 1.25 | C2: =SUM(Details!$C$6:D$6)/SUM(Details!$O$6:P$6) -> 0.98091603 | D2: =SUM(Details!$C$6:E$6)/SUM(Details!$O$6:Q$6) -> 0.96368039 | E2: =SUM(Details!$C$6:F$6)/SUM(Details!$O$6:R$6) -> 0.92411467 | F2: =SUM(Details!$C$6:G$6)/SUM(Details!$O$6:S$6) -> 0.91766268 | G2: =SUM(Details!$C$6:H$6)/SUM(Details!$O$6:T$6) -> 0.932092 | H2: =SUM(Details!$C$6:I$6)/SUM(Details!$O$6:U$6) -> 0.91948765 | I2: =SUM(Details!$C$6:J$6)/SUM(Details!$O$6:V$6) -> 0.93615323 | O2: =Details!AM$6=B2 -> TRUE | P2: =Details!AN$6=C2 -> TRUE | Q2: =Details!AO$6=D2 -> TRUE | R2: =Details!AP$6=E2 -> TRUE | S2: =Details!AQ$6=F2 -> TRUE | T2: =Details!AR$6=G2 -> TRUE | U2: =Details!AS$6=H2 -> TRUE | V2: =Details!AT$6=I2 -> TRUE
B3: =SUM(Details!C$7:$C$7)/SUM(Details!O$7:$O$7) -> 1.0315789 | C3: =SUM(Details!$C$7:D$7)/SUM(Details!$O$7:P$7) -> 0.87659574 | D3: =SUM(Details!$C$7:E$7)/SUM(Details!$O$7:Q$7) -> 0.87027027 | E3: =SUM(Details!$C$7:F$7)/SUM(Details!$O$7:R$7) -> 0.82037037 | F3: =SUM(Details!$C$7:G$7)/SUM(Details!$O$7:S$7) -> 0.8358209 | G3: =SUM(Details!$C$7:H$7)/SUM(Details!$O$7:T$7) -> 0.83902439 | H3: =SUM(Details!$C$7:I$7)/SUM(Details!$O$7:U$7) -> 0.84583333 | I3: =SUM(Details!$C$7:J$7)/SUM(Details!$O$7:V$7) -> 0.86880734 | O3: =Details!AM$7=B3 -> TRUE | P3: =Details!AN$7=C3 -> TRUE | Q3: =Details!AO$7=D3 -> TRUE | R3: =Details!AP$7=E3 -> TRUE | S3: =Details!AQ$7=F3 -> TRUE | T3: =Details!AR$7=G3 -> TRUE | U3: =Details!AS$7=H3 -> TRUE | V3: =Details!AT$7=I3 -> TRUE
B4: =SUM(Details!C$8:$C$8)/SUM(Details!O$8:$O$8) -> 1.0357143 | C4: =SUM(Details!$C$8:D$8)/SUM(Details!$O$8:P$8) -> 0.97741935 | D4: =SUM(Details!$C$8:E$8)/SUM(Details!$O$8:Q$8) -> 0.95 | E4: =SUM(Details!$C$8:F$8)/SUM(Details!$O$8:R$8) -> 0.96470588 | F4: =SUM(Details!$C$8:G$8)/SUM(Details!$O$8:S$8) -> 0.95930233 | G4: =SUM(Details!$C$8:H$8)/SUM(Details!$O$8:T$8) -> 0.95849057 | H4: =SUM(Details!$C$8:I$8)/SUM(Details!$O$8:U$8) -> 0.95238095 | I4: =SUM(Details!$C$8:J$8)/SUM(Details!$O$8:V$8) -> 0.95753425 | O4: =Details!AM$8=B4 -> TRUE | P4: =Details!AN$8=C4 -> TRUE | Q4: =Details!AO$8=D4 -> TRUE | R4: =Details!AP$8=E4 -> TRUE | S4: =Details!AQ$8=F4 -> TRUE | T4: =Details!AR$8=G4 -> TRUE | U4: =Details!AS$8=H4 -> TRUE | V4: =Details!AT$8=I4 -> TRUE
B5: =SUM(Details!C$9:$C$9)/SUM(Details!O$9:$O$9) -> 1.0985075 | C5: =SUM(Details!$C$9:D$9)/SUM(Details!$O$9:P$9) -> 0.94919455 | D5: =SUM(Details!$C$9:E$9)/SUM(Details!$O$9:Q$9) -> 0.93141076 | E5: =SUM(Details!$C$9:F$9)/SUM(Details!$O$9:R$9) -> 0.90843905 | F5: =SUM(Details!$C$9:G$9)/SUM(Details!$O$9:S$9) -> 0.90932983 | G5: =SUM(Details!$C$9:H$9)/SUM(Details!$O$9:T$9) -> 0.91478697 | H5: =SUM(Details!$C$9:I$9)/SUM(Details!$O$9:U$9) -> 0.910655 | I5: =SUM(Details!$C$9:J$9)/SUM(Details!$O$9:V$9) -> 0.92505916 | O5: =Details!AM$9=B5 -> TRUE | P5: =Details!AN$9=C5 -> TRUE | Q5: =Details!AO$9=D5 -> TRUE | R5: =Details!AP$9=E5 -> TRUE | S5: =Details!AQ$9=F5 -> TRUE | T5: =Details!AR$9=G5 -> TRUE | U5: =Details!AS$9=H5 -> TRUE | V5: =Details!AT$9=I5 -> TRUE
B8: =SUM(Details!$C$16:C$16)/SUM(Details!$O$16:O$16) -> 0.94833333 | C8: =SUM(Details!$C$16:D$16)/SUM(Details!$O$16:P$16) -> 0.9408 | D8: =SUM(Details!$C$16:E$16)/SUM(Details!$O$16:Q$16) -> 0.96394737 | E8: =SUM(Details!$C$16:F$16)/SUM(Details!$O$16:R$16) -> 0.96 | F8: =SUM(Details!$C$16:G$16)/SUM(Details!$O$16:S$16) -> 0.97030303 | G8: =SUM(Details!$C$16:H$16)/SUM(Details!$O$16:T$16) -> 0.96439024 | H8: =SUM(Details!$C$16:I$16)/SUM(Details!$O$16:U$16) -> 0.934 | I8: =SUM(Details!$C$16:J$16)/SUM(Details!$O$16:V$16) -> 0.94275862 | O8: =Details!AM$16=B8 -> TRUE | P8: =Details!AN$16=C8 -> TRUE | Q8: =Details!AO$16=D8 -> TRUE | R8: =Details!AP$16=E8 -> TRUE | S8: =Details!AQ$16=F8 -> TRUE | T8: =Details!AR$16=G8 -> TRUE | U8: =Details!AS$16=H8 -> TRUE | V8: =Details!AT$16=I8 -> TRUE
B9: =SUM(Details!$C$17:C$17)/SUM(Details!$O$17:O$17) -> 0.911 | C9: =SUM(Details!$C$17:D$17)/SUM(Details!$O$17:P$17) -> 0.87545455 | D9: =SUM(Details!$C$17:E$17)/SUM(Details!$O$17:Q$17) -> 0.9069697 | E9: =SUM(Details!$C$17:F$17)/SUM(Details!$O$17:R$17) -> 0.91511111 | F9: =SUM(Details!$C$17:G$17)/SUM(Details!$O$17:S$17) -> 0.91754386 | G9: =SUM(Details!$C$17:H$17)/SUM(Details!$O$17:T$17) -> 0.92869565 | H9: =SUM(Details!$C$17:I$17)/SUM(Details!$O$17:U$17) -> 0.93506173 | I9: =SUM(Details!$C$17:J$17)/SUM(Details!$O$17:V$17) -> 0.94946237 | O9: =Details!AM$17=B9 -> TRUE | P9: =Details!AN$17=C9 -> TRUE | Q9: =Details!AO$17=D9 -> TRUE | R9: =Details!AP$17=E9 -> TRUE | S9: =Details!AQ$17=F9 -> TRUE | T9: =Details!AR$17=G9 -> TRUE | U9: =Details!AS$17=H9 -> TRUE | V9: =Details!AT$17=I9 -> TRUE
B10: =SUM(Details!$C$18:C$18)/SUM(Details!$O$18:O$18) -> 1.0038462 | C10: =SUM(Details!$C$18:D$18)/SUM(Details!$O$18:P$18) -> 1.0159259 | D10: =SUM(Details!$C$18:E$18)/SUM(Details!$O$18:Q$18) -> 1.0139535 | E10: =SUM(Details!$C$18:F$18)/SUM(Details!$O$18:R$18) -> 1.0211864 | F10: =SUM(Details!$C$18:G$18)/SUM(Details!$O$18:S$18) -> 1.0266216 | G10: =SUM(Details!$C$18:H$18)/SUM(Details!$O$18:T$18) -> 1.0011702 | H10: =SUM(Details!$C$18:I$18)/SUM(Details!$O$18:U$18) -> 0.99142857 | I10: =SUM(Details!$C$18:J$18)/SUM(Details!$O$18:V$18) -> 0.99730769 | O10: =Details!AM$18=B10 -> TRUE | P10: =Details!AN$18=C10 -> TRUE | Q10: =Details!AO$18=D10 -> TRUE | R10: =Details!AP$18=E10 -> TRUE | S10: =Details!AQ$18=F10 -> TRUE | T10: =Details!AR$18=G10 -> TRUE | U10: =Details!AS$18=H10 -> TRUE | V10: =Details!AT$18=I10 -> TRUE
B11: =SUM(Details!$C$19:C$19)/SUM(Details!$O$19:O$19) -> 0.95828571 | C11: =SUM(Details!$C$19:D$19)/SUM(Details!$O$19:P$19) -> 0.94878378 | D11: =SUM(Details!$C$19:E$19)/SUM(Details!$O$19:Q$19) -> 0.96631579 | E11: =SUM(Details!$C$19:F$19)/SUM(Details!$O$19:R$19) -> 0.97012739 | F11: =SUM(Details!$C$19:G$19)/SUM(Details!$O$19:S$19) -> 0.97619289 | G11: =SUM(Details!$C$19:H$19)/SUM(Details!$O$19:T$19) -> 0.96844898 | H11: =SUM(Details!$C$19:I$19)/SUM(Details!$O$19:U$19) -> 0.95624573 | I11: =SUM(Details!$C$19:J$19)/SUM(Details!$O$19:V$19) -> 0.96551622 | O11: =Details!AM$19=B11 -> TRUE | P11: =Details!AN$19=C11 -> TRUE | Q11: =Details!AO$19=D11 -> TRUE | R11: =Details!AP$19=E11 -> TRUE | S11: =Details!AQ$19=F11 -> TRUE | T11: =Details!AR$19=G11 -> TRUE | U11: =Details!AS$19=H11 -> TRUE | V11: =Details!AT$19=I11 -> TRUE
B14: =SUM(Details!$C$26:C$26)/SUM(Details!$O$26:O$26) -> 1.04 | C14: =SUM(Details!$C$26:D$26)/SUM(Details!$O$26:P$26) -> 1.03 | D14: =SUM(Details!$C$26:E$26)/SUM(Details!$O$26:Q$26) -> 1.04375 | E14: =SUM(Details!$C$26:F$26)/SUM(Details!$O$26:R$26) -> 1.0095238 | F14: =SUM(Details!$C$26:G$26)/SUM(Details!$O$26:S$26) -> 0.94385965 | G14: =SUM(Details!$C$26:H$26)/SUM(Details!$O$26:T$26) -> 0.89166667 | H14: =SUM(Details!$C$26:I$26)/SUM(Details!$O$26:U$26) -> 0.86206897 | I14: =SUM(Details!$C$26:J$26)/SUM(Details!$O$26:V$26) -> 0.88037383 | O14: =Details!AM$26=B14 -> TRUE | P14: =Details!AN$26=C14 -> TRUE | Q14: =Details!AO$26=D14 -> TRUE | R14: =Details!AP$26=E14 -> TRUE | S14: =Details!AQ$26=F14 -> TRUE | T14: =Details!AR$26=G14 -> TRUE | U14: =Details!AS$26=H14 -> TRUE | V14: =Details!AT$26=I14 -> TRUE
B15: =SUM(Details!$C$27:C$27)/SUM(Details!$O$27:O$27) -> 1.03 | C15: =SUM(Details!$C$27:D$27)/SUM(Details!$O$27:P$27) -> 1.04 | D15: =SUM(Details!$C$27:E$27)/SUM(Details!$O$27:Q$27) -> 1.025 | E15: =SUM(Details!$C$27:F$27)/SUM(Details!$O$27:R$27) -> 1.0186047 | F15: =SUM(Details!$C$27:G$27)/SUM(Details!$O$27:S$27) -> 1.1698113 | G15: =SUM(Details!$C$27:H$27)/SUM(Details!$O$27:T$27) -> 1.1867769 | H15: =SUM(Details!$C$27:I$27)/SUM(Details!$O$27:U$27) -> 1.141844 | I15: =SUM(Details!$C$27:J$27)/SUM(Details!$O$27:V$27) -> 1.121118 | O15: =Details!AM$27=B15 -> TRUE | P15: =Details!AN$27=C15 -> TRUE | Q15: =Details!AO$27=D15 -> TRUE | R15: =Details!AP$27=E15 -> TRUE | S15: =Details!AQ$27=F15 -> TRUE | T15: =Details!AR$27=G15 -> TRUE | U15: =Details!AS$27=H15 -> TRUE | V15: =Details!AT$27=I15 -> TRUE
B16: =SUM(Details!$C$28:C$28)/SUM(Details!$O$28:O$28) -> 1.16 | C16: =SUM(Details!$C$28:D$28)/SUM(Details!$O$28:P$28) -> 1.17 | D16: =SUM(Details!$C$28:E$28)/SUM(Details!$O$28:Q$28) -> 1.0725 | E16: =SUM(Details!$C$28:F$28)/SUM(Details!$O$28:R$28) -> 1.26 | F16: =SUM(Details!$C$28:G$28)/SUM(Details!$O$28:S$28) -> 1.4575 | G16: =SUM(Details!$C$28:H$28)/SUM(Details!$O$28:T$28) -> 1.381 | H16: =SUM(Details!$C$28:I$28)/SUM(Details!$O$28:U$28) -> 1.3208696 | I16: =SUM(Details!$C$28:J$28)/SUM(Details!$O$28:V$28) -> 1.3614815 | O16: =Details!AM$28=B16 -> TRUE | P16: =Details!AN$28=C16 -> TRUE | Q16: =Details!AO$28=D16 -> TRUE | R16: =Details!AP$28=E16 -> TRUE | S16: =Details!AQ$28=F16 -> TRUE | T16: =Details!AR$28=G16 -> TRUE | U16: =Details!AS$28=H16 -> TRUE | V16: =Details!AT$28=I16 -> TRUE
B17: =SUM(Details!$C$29:C$29)/SUM(Details!$O$29:O$29) -> 1.065 | C17: =SUM(Details!$C$29:D$29)/SUM(Details!$O$29:P$29) -> 1.07 | D17: =SUM(Details!$C$29:E$29)/SUM(Details!$O$29:Q$29) -> 1.0428571 | E17: =SUM(Details!$C$29:F$29)/SUM(Details!$O$29:R$29) -> 1.093617 | F17: =SUM(Details!$C$29:G$29)/SUM(Details!$O$29:S$29) -> 1.2115226 | G17: =SUM(Details!$C$29:H$29)/SUM(Details!$O$29:T$29) -> 1.1805461 | H17: =SUM(Details!$C$29:I$29)/SUM(Details!$O$29:U$29) -> 1.1309038 | I17: =SUM(Details!$C$29:J$29)/SUM(Details!$O$29:V$29) -> 1.1377171 | O17: =Details!AM$29=B17 -> TRUE | P17: =Details!AN$29=C17 -> TRUE | Q17: =Details!AO$29=D17 -> TRUE | R17: =Details!AP$29=E17 -> TRUE | S17: =Details!AQ$29=F17 -> TRUE | T17: =Details!AR$29=G17 -> TRUE | U17: =Details!AS$29=H17 -> TRUE | V17: =Details!AT$29=I17 -> TRUE

Sheet Charts
A1: Aug
A3: Type | B3: Value | C3: Target
A4: Order Accepted | B4: =SUM(Details!$C$9:$N$9) -> 35180000 | C4: =SUM(Details!$O$9:$Z$9) -> 38030000
A5: Order Delivered | B5: =SUM(Details!$C$19:$N$19) -> 32731000 | C5: =SUM(Details!$O$19:$Z$19) -> 33900000
A6: Churn | B6: =SUM(Details!$C$29:$N$29) -> 4585000 | C6: =SUM(Details!$O$29:$Z$29) -> 4030000
A9: Product A_OA | F9: Product B_OA | K9: Product C_OA
A11: Month | B11: Value | C11: Target | F11: Month | G11: Value | H11: Target | K11: Month | L11: Value | M11: Target
A12: Jan | B12: =INDEX(Details!$C$6:$N$6,MATCH($A12,Details!$C$5:$N$5,0)) -> 1250000 | C12: =INDEX(Details!$O$6:$Z$6,MATCH($A12,Details!$O$5:$Z$5,0)) -> 1000000 | F12: Jan | G12: =INDEX(Details!$C$7:$N$7,MATCH($F12,Details!$C$5:$N$5,0)) -> 980000 | H12: =INDEX(Details!$O$7:$Z$7,MATCH($F12,Details!$O$5:$Z$5,0)) -> 950000 | K12: Jan | L12: =INDEX(Details!$C$8:$N$8,MATCH($K12,Details!$C$5:$N$5,0)) -> 1450000 | M12: =INDEX(Details!$O$8:$Z$8,MATCH($K12,Details!$O$5:$Z$5,0)) -> 1400000
A13: Feb | B13: =INDEX(Details!$C$6:$N$6,MATCH($A13,Details!$C$5:$N$5,0)) -> 1320000 | C13: =INDEX(Details!$O$6:$Z$6,MATCH($A13,Details!$O$5:$Z$5,0)) -> 1620000 | F13: Feb | G13: =INDEX(Details!$C$7:$N$7,MATCH($F13,Details!$C$5:$N$5,0)) -> 1080000 | H13: =INDEX(Details!$O$7:$Z$7,MATCH($F13,Details!$O$5:$Z$5,0)) -> 1400000 | K13: Feb | L13: =INDEX(Details!$C$8:$N$8,MATCH($K13,Details!$C$5:$N$5,0)) -> 1580000 | M13: =INDEX(Details!$O$8:$Z$8,MATCH($K13,Details!$O$5:$Z$5,0)) -> 1700000
A14: Mar | B14: =INDEX(Details!$C$6:$N$6,MATCH($A14,Details!$C$5:$N$5,0)) -> 1410000 | C14: =INDEX(Details!$O$6:$Z$6,MATCH($A14,Details!$O$5:$Z$5,0)) -> 1510000 | F14: Mar | G14: =INDEX(Details!$C$7:$N$7,MATCH($F14,Details!$C$5:$N$5,0)) -> 1160000 | H14: =INDEX(Details!$O$7:$Z$7,MATCH($F14,Details!$O$5:$Z$5,0)) -> 1350000 | K14: Mar | L14: =INDEX(Details!$C$8:$N$8,MATCH($K14,Details!$C$5:$N$5,0)) -> 1720000 | M14: =INDEX(Details!$O$8:$Z$8,MATCH($K14,Details!$O$5:$Z$5,0)) -> 1900000
A15: Apr | B15: =INDEX(Details!$C$6:$N$6,MATCH($A15,Details!$C$5:$N$5,0)) -> 1500000 | C15: =INDEX(Details!$O$6:$Z$6,MATCH($A15,Details!$O$5:$Z$5,0)) -> 1800000 | F15: Apr | G15: =INDEX(Details!$C$7:$N$7,MATCH($F15,Details!$C$5:$N$5,0)) -> 1210000 | H15: =INDEX(Details!$O$7:$Z$7,MATCH($F15,Details!$O$5:$Z$5,0)) -> 1700000 | K15: Apr | L15: =INDEX(Details!$C$8:$N$8,MATCH($K15,Details!$C$5:$N$5,0)) -> 1810000 | M15: =INDEX(Details!$O$8:$Z$8,MATCH($K15,Details!$O$5:$Z$5,0)) -> 1800000
A16: May | B16: =INDEX(Details!$C$6:$N$6,MATCH($A16,Details!$C$5:$N$5,0)) -> 1430000 | C16: =INDEX(Details!$O$6:$Z$6,MATCH($A16,Details!$O$5:$Z$5,0)) -> 1600000 | F16: May | G16: =INDEX(Details!$C$7:$N$7,MATCH($F16,Details!$C$5:$N$5,0)) -> 1170000 | H16: =INDEX(Details!$O$7:$Z$7,MATCH($F16,Details!$O$5:$Z$5,0)) -> 1300000 | K16: May | L16: =INDEX(Details!$C$8:$N$8,MATCH($K16,Details!$C$5:$N$5,0)) -> 1690000 | M16: =INDEX(Details!$O$8:$Z$8,MATCH($K16,Details!$O$5:$Z$5,0)) -> 1800000
A17: Jun | B17: =INDEX(Details!$C$6:$N$6,MATCH($A17,Details!$C$5:$N$5,0)) -> 1600000 | C17: =INDEX(Details!$O$6:$Z$6,MATCH($A17,Details!$O$5:$Z$5,0)) -> 1600000 | F17: Jun | G17: =INDEX(Details!$C$7:$N$7,MATCH($F17,Details!$C$5:$N$5,0)) -> 1280000 | H17: =INDEX(Details!$O$7:$Z$7,MATCH($F17,Details!$O$5:$Z$5,0)) -> 1500000 | K17: Jun | L17: =INDEX(Details!$C$8:$N$8,MATCH($K17,Details!$C$5:$N$5,0)) -> 1910000 | M17: =INDEX(Details!$O$8:$Z$8,MATCH($K17,Details!$O$5:$Z$5,0)) -> 2000000
A18: Jul | B18: =INDEX(Details!$C$6:$N$6,MATCH($A18,Details!$C$5:$N$5,0)) -> 1540000 | C18: =INDEX(Details!$O$6:$Z$6,MATCH($A18,Details!$O$5:$Z$5,0)) -> 1800000 | F18: Jul | G18: =INDEX(Details!$C$7:$N$7,MATCH($F18,Details!$C$5:$N$5,0)) -> 1240000 | H18: =INDEX(Details!$O$7:$Z$7,MATCH($F18,Details!$O$5:$Z$5,0)) -> 1400000 | K18: Jul | L18: =INDEX(Details!$C$8:$N$8,MATCH($K18,Details!$C$5:$N$5,0)) -> 1840000 | M18: =INDEX(Details!$O$8:$Z$8,MATCH($K18,Details!$O$5:$Z$5,0)) -> 2000000
A19: Aug | B19: =INDEX(Details!$C$6:$N$6,MATCH($A19,Details!$C$5:$N$5,0)) -> 1680000 | C19: =INDEX(Details!$O$6:$Z$6,MATCH($A19,Details!$O$5:$Z$5,0)) -> 1600000 | F19: Aug | G19: =INDEX(Details!$C$7:$N$7,MATCH($F19,Details!$C$5:$N$5,0)) -> 1350000 | H19: =INDEX(Details!$O$7:$Z$7,MATCH($F19,Details!$O$5:$Z$5,0)) -> 1300000 | K19: Aug | L19: =INDEX(Details!$C$8:$N$8,MATCH($K19,Details!$C$5:$N$5,0)) -> 1980000 | M19: =INDEX(Details!$O$8:$Z$8,MATCH($K19,Details!$O$5:$Z$5,0)) -> 2000000
A20: Sep | F20: Sep | K20: Sep
A21: Oct | F21: Oct | K21: Oct
A22: Nov | F22: Nov | K22: Nov
A23: Dec | F23: Dec | K23: Dec
A26: Product A_OD | F26: Product B_OD | K26: Product C_OD
A28: Month | B28: Value | C28: Target | F28: Month | G28: Value | H28: Target | K28: Month | L28: Value | M28: Target
A29: Jan | B29: =INDEX(Details!$C$16:$N$16,MATCH($A29,Details!$C$15:$N$15,0)) -> 1138000 | C29: =INDEX(Details!$O$16:$Z$16,MATCH($A29,Details!$O$15:$Z$15,0)) -> 1200000 | F29: Jan | G29: =INDEX(Details!$C$17:$N$17,MATCH($F29,Details!$C$15:$N$15,0)) -> 911000 | H29: =INDEX(Details!$O$17:$Z$17,MATCH($F29,Details!$O$15:$Z$15,0)) -> 1000000 | K29: Jan | L29: =INDEX(Details!$C$18:$N$18,MATCH($K29,Details!$C$15:$N$15,0)) -> 1305000 | M29: =INDEX(Details!$O$18:$Z$18,MATCH($K29,Details!$O$15:$Z$15,0)) -> 1300000
A30: Feb | B30: =INDEX(Details!$C$16:$N$16,MATCH($A30,Details!$C$15:$N$15,0)) -> 1214000 | C30: =INDEX(Details!$O$16:$Z$16,MATCH($A30,Details!$O$15:$Z$15,0)) -> 1300000 | F30: Feb | G30: =INDEX(Details!$C$17:$N$17,MATCH($F30,Details!$C$15:$N$15,0)) -> 1015000 | H30: =INDEX(Details!$O$17:$Z$17,MATCH($F30,Details!$O$15:$Z$15,0)) -> 1200000 | K30: Feb | L30: =INDEX(Details!$C$18:$N$18,MATCH($K30,Details!$C$15:$N$15,0)) -> 1438000 | M30: =INDEX(Details!$O$18:$Z$18,MATCH($K30,Details!$O$15:$Z$15,0)) -> 1400000
A31: Mar | B31: =INDEX(Details!$C$16:$N$16,MATCH($A31,Details!$C$15:$N$15,0)) -> 1311000 | C31: =INDEX(Details!$O$16:$Z$16,MATCH($A31,Details!$O$15:$Z$15,0)) -> 1300000 | F31: Mar | G31: =INDEX(Details!$C$17:$N$17,MATCH($F31,Details!$C$15:$N$15,0)) -> 1067000 | H31: =INDEX(Details!$O$17:$Z$17,MATCH($F31,Details!$O$15:$Z$15,0)) -> 1100000 | K31: Mar | L31: =INDEX(Details!$C$18:$N$18,MATCH($K31,Details!$C$15:$N$15,0)) -> 1617000 | M31: =INDEX(Details!$O$18:$Z$18,MATCH($K31,Details!$O$15:$Z$15,0)) -> 1600000
A32: Apr | B32: =INDEX(Details!$C$16:$N$16,MATCH($A32,Details!$C$15:$N$15,0)) -> 1425000 | C32: =INDEX(Details!$O$16:$Z$16,MATCH($A32,Details!$O$15:$Z$15,0)) -> 1500000 | F32: Apr | G32: =INDEX(Details!$C$17:$N$17,MATCH($F32,Details!$C$15:$N$15,0)) -> 1125000 | H32: =INDEX(Details!$O$17:$Z$17,MATCH($F32,Details!$O$15:$Z$15,0)) -> 1200000 | K32: Apr | L32: =INDEX(Details!$C$18:$N$18,MATCH($K32,Details!$C$15:$N$15,0)) -> 1665000 | M32: =INDEX(Details!$O$18:$Z$18,MATCH($K32,Details!$O$15:$Z$15,0)) -> 1600000
A33: May | B33: =INDEX(Details!$C$16:$N$16,MATCH($A33,Details!$C$15:$N$15,0)) -> 1316000 | C33: =INDEX(Details!$O$16:$Z$16,MATCH($A33,Details!$O$15:$Z$15,0)) -> 1300000 | F33: May | G33: =INDEX(Details!$C$17:$N$17,MATCH($F33,Details!$C$15:$N$15,0)) -> 1112000 | H33: =INDEX(Details!$O$17:$Z$17,MATCH($F33,Details!$O$15:$Z$15,0)) -> 1200000 | K33: May | L33: =INDEX(Details!$C$18:$N$18,MATCH($K33,Details!$C$15:$N$15,0)) -> 1572000 | M33: =INDEX(Details!$O$18:$Z$18,MATCH($K33,Details!$O$15:$Z$15,0)) -> 1500000
A34: Jun | B34: =INDEX(Details!$C$16:$N$16,MATCH($A34,Details!$C$15:$N$15,0)) -> 1504000 | C34: =INDEX(Details!$O$16:$Z$16,MATCH($A34,Details!$O$15:$Z$15,0)) -> 1600000 | F34: Jun | G34: =INDEX(Details!$C$17:$N$17,MATCH($F34,Details!$C$15:$N$15,0)) -> 1178000 | H34: =INDEX(Details!$O$17:$Z$17,MATCH($F34,Details!$O$15:$Z$15,0)) -> 1200000 | K34: Jun | L34: =INDEX(Details!$C$18:$N$18,MATCH($K34,Details!$C$15:$N$15,0)) -> 1814000 | M34: =INDEX(Details!$O$18:$Z$18,MATCH($K34,Details!$O$15:$Z$15,0)) -> 2000000
A35: Jul | B35: =INDEX(Details!$C$16:$N$16,MATCH($A35,Details!$C$15:$N$15,0)) -> 1432000 | C35: =INDEX(Details!$O$16:$Z$16,MATCH($A35,Details!$O$15:$Z$15,0)) -> 1800000 | F35: Jul | G35: =INDEX(Details!$C$17:$N$17,MATCH($F35,Details!$C$15:$N$15,0)) -> 1166000 | H35: =INDEX(Details!$O$17:$Z$17,MATCH($F35,Details!$O$15:$Z$15,0)) -> 1200000 | K35: Jul | L35: =INDEX(Details!$C$18:$N$18,MATCH($K35,Details!$C$15:$N$15,0)) -> 1693000 | M35: =INDEX(Details!$O$18:$Z$18,MATCH($K35,Details!$O$15:$Z$15,0)) -> 1800000
A36: Aug | B36: =INDEX(Details!$C$16:$N$16,MATCH($A36,Details!$C$15:$N$15,0)) -> 1596000 | C36: =INDEX(Details!$O$16:$Z$16,MATCH($A36,Details!$O$15:$Z$15,0)) -> 1600000 | F36: Aug | G36: =INDEX(Details!$C$17:$N$17,MATCH($F36,Details!$C$15:$N$15,0)) -> 1256000 | H36: =INDEX(Details!$O$17:$Z$17,MATCH($F36,Details!$O$15:$Z$15,0)) -> 1200000 | K36: Aug | L36: =INDEX(Details!$C$18:$N$18,MATCH($K36,Details!$C$15:$N$15,0)) -> 1861000 | M36: =INDEX(Details!$O$18:$Z$18,MATCH($K36,Details!$O$15:$Z$15,0)) -> 1800000
A37: Sep | F37: Sep | K37: Sep
A38: Oct | F38: Oct | K38: Oct
A39: Nov | F39: Nov | K39: Nov
A40: Dec | F40: Dec | K40: Dec
A43: Product A_Churn | F43: Product B_Churn | K43: Product C_Churn
A45: Month | B45: Value | C45: Target | F45: Month | G45: Value | H45: Target | K45: Month | L45: Value | M45: Target
A46: Jan | B46: =INDEX(Details!$C$26:$N$26,MATCH($A46,Details!$C$25:$N$25,0)) -> 104000 | C46: =INDEX(Details!$O$26:$Z$26,MATCH($A46,Details!$O$25:$Z$25,0)) -> 100000 | F46: Jan | G46: =INDEX(Details!$C$27:$N$27,MATCH($F46,Details!$C$25:$N$25,0)) -> 206000 | H46: =INDEX(Details!$O$27:$Z$27,MATCH($F46,Details!$O$25:$Z$25,0)) -> 200000 | K46: Jan | L46: =INDEX(Details!$C$28:$N$28,MATCH($K46,Details!$C$25:$N$25,0)) -> 116000 | M46: =INDEX(Details!$O$28:$Z$28,MATCH($K46,Details!$O$25:$Z$25,0)) -> 100000
A47: Feb | B47: =INDEX(Details!$C$26:$N$26,MATCH($A47,Details!$C$25:$N$25,0)) -> 102000 | C47: =INDEX(Details!$O$26:$Z$26,MATCH($A47,Details!$O$25:$Z$25,0)) -> 100000 | F47: Feb | G47: =INDEX(Details!$C$27:$N$27,MATCH($F47,Details!$C$25:$N$25,0)) -> 210000 | H47: =INDEX(Details!$O$27:$Z$27,MATCH($F47,Details!$O$25:$Z$25,0)) -> 200000 | K47: Feb | L47: =INDEX(Details!$C$28:$N$28,MATCH($K47,Details!$C$25:$N$25,0)) -> 118000 | M47: =INDEX(Details!$O$28:$Z$28,MATCH($K47,Details!$O$25:$Z$25,0)) -> 100000
A48: Mar | B48: =INDEX(Details!$C$26:$N$26,MATCH($A48,Details!$C$25:$N$25,0)) -> 128000 | C48: =INDEX(Details!$O$26:$Z$26,MATCH($A48,Details!$O$25:$Z$25,0)) -> 120000 | F48: Mar | G48: =INDEX(Details!$C$27:$N$27,MATCH($F48,Details!$C$25:$N$25,0)) -> 281000 | H48: =INDEX(Details!$O$27:$Z$27,MATCH($F48,Details!$O$25:$Z$25,0)) -> 280000 | K48: Mar | L48: =INDEX(Details!$C$28:$N$28,MATCH($K48,Details!$C$25:$N$25,0)) -> 195000 | M48: =INDEX(Details!$O$28:$Z$28,MATCH($K48,Details!$O$25:$Z$25,0)) -> 200000
A49: Apr | B49: =INDEX(Details!$C$26:$N$26,MATCH($A49,Details!$C$25:$N$25,0)) -> 90000 | C49: =INDEX(Details!$O$26:$Z$26,MATCH($A49,Details!$O$25:$Z$25,0)) -> 100000 | F49: Apr | G49: =INDEX(Details!$C$27:$N$27,MATCH($F49,Details!$C$25:$N$25,0)) -> 179000 | H49: =INDEX(Details!$O$27:$Z$27,MATCH($F49,Details!$O$25:$Z$25,0)) -> 180000 | K49: Apr | L49: =INDEX(Details!$C$28:$N$28,MATCH($K49,Details!$C$25:$N$25,0)) -> 327000 | M49: =INDEX(Details!$O$28:$Z$28,MATCH($K49,Details!$O$25:$Z$25,0)) -> 200000
A50: May | B50: =INDEX(Details!$C$26:$N$26,MATCH($A50,Details!$C$25:$N$25,0)) -> 114000 | C50: =INDEX(Details!$O$26:$Z$26,MATCH($A50,Details!$O$25:$Z$25,0)) -> 150000 | F50: May | G50: =INDEX(Details!$C$27:$N$27,MATCH($F50,Details!$C$25:$N$25,0)) -> 364000 | H50: =INDEX(Details!$O$27:$Z$27,MATCH($F50,Details!$O$25:$Z$25,0)) -> 200000 | K50: May | L50: =INDEX(Details!$C$28:$N$28,MATCH($K50,Details!$C$25:$N$25,0)) -> 410000 | M50: =INDEX(Details!$O$28:$Z$28,MATCH($K50,Details!$O$25:$Z$25,0)) -> 200000
...

Sheet Details
B2: Order Accepted
B4: LOP | C4: Value | O4: Target | AA4: Value vs Target | AM4: Cumulative
B5: Product | C5: ='Order Accepted'!F11 -> Jan | D5: ='Order Accepted'!G4 -> Feb | E5: ='Order Accepted'!H4 -> Mar | F5: ='Order Accepted'!I4 -> Apr | G5: ='Order Accepted'!J4 -> May | H5: ='Order Accepted'!K4 -> Jun | I5: ='Order Accepted'!L4 -> Jul | J5: ='Order Accepted'!M4 -> Aug | O5: =OA_Target!F4 -> Jan | P5: =OA_Target!G4 -> Feb | Q5: =OA_Target!H4 -> Mar | R5: =OA_Target!I4 -> Apr | S5: =OA_Target!J4 -> May | T5: =OA_Target!K4 -> Jun | U5: =OA_Target!L4 -> Jul | V5: =OA_Target!M4 -> Aug | AA5: Jan | AB5: Feb | AC5: Mar | AD5: Apr | AE5: May | AF5: Jun | AG5: Jul | AH5: Aug | AI5: Sep | AJ5: Oct | AK5: Nov | AL5: Dec | AM5: Jan | AN5: Feb | AO5: Mar | AP5: Apr | AQ5: May | AR5: Jun | AS5: Jul | AT5: Aug | AU5: Sep | AV5: Oct | AW5: Nov | AX5: Dec
B6: Product A | C6: =INDEX('Order Accepted'!$F5:$N5,MATCH(C$5,'Order Accepted'!$F4:$N4,0)) -> 1250000 | D6: =INDEX('Order Accepted'!$F5:$N5,MATCH(D$5,'Order Accepted'!$F4:$N4,0)) -> 1320000 | E6: =INDEX('Order Accepted'!$F5:$N5,MATCH(E$5,'Order Accepted'!$F4:$N4,0)) -> 1410000 | F6: =INDEX('Order Accepted'!$F5:$N5,MATCH(F$5,'Order Accepted'!$F4:$N4,0)) -> 1500000 | G6: =INDEX('Order Accepted'!$F5:$N5,MATCH(G$5,'Order Accepted'!$F4:$N4,0)) -> 1430000 | H6: =INDEX('Order Accepted'!$F5:$N5,MATCH(H$5,'Order Accepted'!$F4:$N4,0)) -> 1600000 | I6: =INDEX('Order Accepted'!$F5:$N5,MATCH(I$5,'Order Accepted'!$F4:$N4,0)) -> 1540000 | J6: =INDEX('Order Accepted'!$F5:$N5,MATCH(J$5,'Order Accepted'!$F4:$N4,0)) -> 1680000 | O6: =INDEX(OA_Target!$F5:$N5,MATCH(C$5,OA_Target!$F4:$N4,0)) -> 1000000 | P6: =INDEX(OA_Target!$F5:$N5,MATCH(D$5,OA_Target!$F4:$N4,0)) -> 1620000 | Q6: =INDEX(OA_Target!$F5:$N5,MATCH(E$5,OA_Target!$F4:$N4,0)) -> 1510000 | R6: =INDEX(OA_Target!$F5:$N5,MATCH(F$5,OA_Target!$F4:$N4,0)) -> 1800000 | S6: =INDEX(OA_Target!$F5:$N5,MATCH(G$5,OA_Target!$F4:$N4,0)) -> 1600000 | T6: =INDEX(OA_Target!$F5:$N5,MATCH(H$5,OA_Target!$F4:$N4,0)) -> 1600000 | U6: =INDEX(OA_Target!$F5:$N5,MATCH(I$5,OA_Target!$F4:$N4,0)) -> 1800000 | V6: =INDEX(OA_Target!$F5:$N5,MATCH(J$5,OA_Target!$F4:$N4,0)) -> 1600000 | AA6: =C6/O6 -> 1.25 | AB6: =D6/P6 -> 0.81481481 | AC6: =E6/Q6 -> 0.93377483 | AD6: =F6/R6 -> 0.83333333 | AE6: =G6/S6 -> 0.89375 | AF6: =H6/T6 -> 1 | AG6: =I6/U6 -> 0.85555556 | AH6: =J6/V6 -> 1.05 | AM6: =SUM($C6:INDEX($C6:$N6,1,MATCH(AM$5,$C$5:$N$5,0)))/SUM($O6:INDEX($O6:$Z6,1,MATCH(AM$5,$O$5:$Z$5,0))) -> 1.25 | AN6: =SUM($C6:INDEX($C6:$N6,1,MATCH(AN$5,$C$5:$N$5,0)))/SUM($O6:INDEX($O6:$Z6,1,MATCH(AN$5,$O$5:$Z$5,0))) -> 0.98091603 | AO6: =SUM($C6:INDEX($C6:$N6,1,MATCH(AO$5,$C$5:$N$5,0)))/SUM($O6:INDEX($O6:$Z6,1,MATCH(AO$5,$O$5:$Z$5,0))) -> 0.96368039 | AP6: =SUM($C6:INDEX($C6:$N6,1,MATCH(AP$5,$C$5:$N$5,0)))/SUM($O6:INDEX($O6:$Z6,1,MATCH(AP$5,$O$5:$Z$5,0))) -> 0.92411467 | AQ6: =SUM($C6:INDEX($C6:$N6,1,MATCH(AQ$5,$C$5:$N$5,0)))/SUM($O6:INDEX($O6:$Z6,1,MATCH(AQ$5,$O$5:$Z$5,0))) -> 0.91766268 | AR6: =SUM($C6:INDEX($C6:$N6,1,MATCH(AR$5,$C$5:$N$5,0)))/SUM($O6:INDEX($O6:$Z6,1,MATCH(AR$5,$O$5:$Z$5,0))) -> 0.932092 | AS6: =SUM($C6:INDEX($C6:$N6,1,MATCH(AS$5,$C$5:$N$5,0)))/SUM($O6:INDEX($O6:$Z6,1,MATCH(AS$5,$O$5:$Z$5,0))) -> 0.91948765 | AT6: =SUM($C6:INDEX($C6:$N6,1,MATCH(AT$5,$C$5:$N$5,0)))/SUM($O6:INDEX($O6:$Z6,1,MATCH(AT$5,$O$5:$Z$5,0))) -> 0.93615323
B7: Product B | C7: =INDEX('Order Accepted'!$F12:$N12,MATCH(C$5,'Order Accepted'!$F11:$N11,0)) -> 980000 | D7: =INDEX('Order Accepted'!$F12:$N12,MATCH(D$5,'Order Accepted'!$F11:$N11,0)) -> 1080000 | E7: =INDEX('Order Accepted'!$F12:$N12,MATCH(E$5,'Order Accepted'!$F11:$N11,0)) -> 1160000 | F7: =INDEX('Order Accepted'!$F12:$N12,MATCH(F$5,'Order Accepted'!$F11:$N11,0)) -> 1210000 | G7: =INDEX('Order Accepted'!$F12:$N12,MATCH(G$5,'Order Accepted'!$F11:$N11,0)) -> 1170000 | H7: =INDEX('Order Accepted'!$F12:$N12,MATCH(H$5,'Order Accepted'!$F11:$N11,0)) -> 1280000 | I7: =INDEX('Order Accepted'!$F12:$N12,MATCH(I$5,'Order Accepted'!$F11:$N11,0)) -> 1240000 | J7: =INDEX('Order Accepted'!$F12:$N12,MATCH(J$5,'Order Accepted'!$F11:$N11,0)) -> 1350000 | O7: =INDEX(OA_Target!$F12:$N12,MATCH(O$5,OA_Target!$F11:$N11,0)) -> 950000 | P7: =INDEX(OA_Target!$F12:$N12,MATCH(P$5,OA_Target!$F11:$N11,0)) -> 1400000 | Q7: =INDEX(OA_Target!$F12:$N12,MATCH(Q$5,OA_Target!$F11:$N11,0)) -> 1350000 | R7: =INDEX(OA_Target!$F12:$N12,MATCH(R$5,OA_Target!$F11:$N11,0)) -> 1700000 | S7: =INDEX(OA_Target!$F12:$N12,MATCH(S$5,OA_Target!$F11:$N11,0)) -> 1300000 | T7: =INDEX(OA_Target!$F12:$N12,MATCH(T$5,OA_Target!$F11:$N11,0)) -> 1500000 | U7: =INDEX(OA_Target!$F12:$N12,MATCH(U$5,OA_Target!$F11:$N11,0)) -> 1400000 | V7: =INDEX(OA_Target!$F12:$N12,MATCH(V$5,OA_Target!$F11:$N11,0)) -> 1300000 | AA7: =C7/O7 -> 1.0315789 | AB7: =D7/P7 -> 0.77142857 | AC7: =E7/Q7 -> 0.85925926 | AD7: =F7/R7 -> 0.71176471 | AE7: =G7/S7 -> 0.9 | AF7: =H7/T7 -> 0.85333333 | AG7: =I7/U7 -> 0.88571429 | AH7: =J7/V7 -> 1.0384615 | AM7: =SUM($C7:INDEX($C7:$N7,1,MATCH(AM$5,$C$5:$N$5,0)))/SUM($O7:INDEX($O7:$Z7,1,MATCH(AM$5,$O$5:$Z$5,0))) -> 1.0315789 | AN7: =SUM($C7:INDEX($C7:$N7,1,MATCH(AN$5,$C$5:$N$5,0)))/SUM($O7:INDEX($O7:$Z7,1,MATCH(AN$5,$O$5:$Z$5,0))) -> 0.87659574 | AO7: =SUM($C7:INDEX($C7:$N7,1,MATCH(AO$5,$C$5:$N$5,0)))/SUM($O7:INDEX($O7:$Z7,1,MATCH(AO$5,$O$5:$Z$5,0))) -> 0.87027027 | AP7: =SUM($C7:INDEX($C7:$N7,1,MATCH(AP$5,$C$5:$N$5,0)))/SUM($O7:INDEX($O7:$Z7,1,MATCH(AP$5,$O$5:$Z$5,0))) -> 0.82037037 | AQ7: =SUM($C7:INDEX($C7:$N7,1,MATCH(AQ$5,$C$5:$N$5,0)))/SUM($O7:INDEX($O7:$Z7,1,MATCH(AQ$5,$O$5:$Z$5,0))) -> 0.8358209 | AR7: =SUM($C7:INDEX($C7:$N7,1,MATCH(AR$5,$C$5:$N$5,0)))/SUM($O7:INDEX($O7:$Z7,1,MATCH(AR$5,$O$5:$Z$5,0))) -> 0.83902439 | AS7: =SUM($C7:INDEX($C7:$N7,1,MATCH(AS$5,$C$5:$N$5,0)))/SUM($O7:INDEX($O7:$Z7,1,MATCH(AS$5,$O$5:$Z$5,0))) -> 0.84583333 | AT7: =SUM($C7:INDEX($C7:$N7,1,MATCH(AT$5,$C$5:$N$5,0)))/SUM($O7:INDEX($O7:$Z7,1,MATCH(AT$5,$O$5:$Z$5,0))) -> 0.86880734
B8: Product C | C8: =INDEX('Order Accepted'!$F19:$N19,MATCH(C$5,'Order Accepted'!$F18:$N18,0)) -> 1450000 | D8: =INDEX('Order Accepted'!$F19:$N19,MATCH(D$5,'Order Accepted'!$F18:$N18,0)) -> 1580000 | E8: =INDEX('Order Accepted'!$F19:$N19,MATCH(E$5,'Order Accepted'!$F18:$N18,0)) -> 1720000 | F8: =INDEX('Order Accepted'!$F19:$N19,MATCH(F$5,'Order Accepted'!$F18:$N18,0)) -> 1810000 | G8: =INDEX('Order Accepted'!$F19:$N19,MATCH(G$5,'Order Accepted'!$F18:$N18,0)) -> 1690000 | H8: =INDEX('Order Accepted'!$F19:$N19,MATCH(H$5,'Order Accepted'!$F18:$N18,0)) -> 1910000 | I8: =INDEX('Order Accepted'!$F19:$N19,MATCH(I$5,'Order Accepted'!$F18:$N18,0)) -> 1840000 | J8: =INDEX('Order Accepted'!$F19:$N19,MATCH(J$5,'Order Accepted'!$F18:$N18,0)) -> 1980000 | O8: =INDEX(OA_Target!$F19:$N19,MATCH(O$5,OA_Target!$F18:$N18,0)) -> 1400000 | P8: =INDEX(OA_Target!$F19:$N19,MATCH(P$5,OA_Target!$F18:$N18,0)) -> 1700000 | Q8: =INDEX(OA_Target!$F19:$N19,MATCH(Q$5,OA_Target!$F18:$N18,0)) -> 1900000 | R8: =INDEX(OA_Target!$F19:$N19,MATCH(R$5,OA_Target!$F18:$N18,0)) -> 1800000 | S8: =INDEX(OA_Target!$F19:$N19,MATCH(S$5,OA_Target!$F18:$N18,0)) -> 1800000 | T8: =INDEX(OA_Target!$F19:$N19,MATCH(T$5,OA_Target!$F18:$N18,0)) -> 2000000 | U8: =INDEX(OA_Target!$F19:$N19,MATCH(U$5,OA_Target!$F18:$N18,0)) -> 2000000 | V8: =INDEX(OA_Target!$F19:$N19,MATCH(V$5,OA_Target!$F18:$N18,0)) -> 2000000 | AA8: =C8/O8 -> 1.0357143 | AB8: =D8/P8 -> 0.92941176 | AC8: =E8/Q8 -> 0.90526316 | AD8: =F8/R8 -> 1.0055556 | AE8: =G8/S8 -> 0.93888889 | AF8: =H8/T8 -> 0.955 | AG8: =I8/U8 -> 0.92 | AH8: =J8/V8 -> 0.99 | AM8: =SUM($C8:INDEX($C8:$N8,1,MATCH(AM$5,$C$5:$N$5,0)))/SUM($O8:INDEX($O8:$Z8,1,MATCH(AM$5,$O$5:$Z$5,0))) -> 1.0357143 | AN8: =SUM($C8:INDEX($C8:$N8,1,MATCH(AN$5,$C$5:$N$5,0)))/SUM($O8:INDEX($O8:$Z8,1,MATCH(AN$5,$O$5:$Z$5,0))) -> 0.97741935 | AO8: =SUM($C8:INDEX($C8:$N8,1,MATCH(AO$5,$C$5:$N$5,0)))/SUM($O8:INDEX($O8:$Z8,1,MATCH(AO$5,$O$5:$Z$5,0))) -> 0.95 | AP8: =SUM($C8:INDEX($C8:$N8,1,MATCH(AP$5,$C$5:$N$5,0)))/SUM($O8:INDEX($O8:$Z8,1,MATCH(AP$5,$O$5:$Z$5,0))) -> 0.96470588 | AQ8: =SUM($C8:INDEX($C8:$N8,1,MATCH(AQ$5,$C$5:$N$5,0)))/SUM($O8:INDEX($O8:$Z8,1,MATCH(AQ$5,$O$5:$Z$5,0))) -> 0.95930233 | AR8: =SUM($C8:INDEX($C8:$N8,1,MATCH(AR$5,$C$5:$N$5,0)))/SUM($O8:INDEX($O8:$Z8,1,MATCH(AR$5,$O$5:$Z$5,0))) -> 0.95849057 | AS8: =SUM($C8:INDEX($C8:$N8,1,MATCH(AS$5,$C$5:$N$5,0)))/SUM($O8:INDEX($O8:$Z8,1,MATCH(AS$5,$O$5:$Z$5,0))) -> 0.95238095 | AT8: =SUM($C8:INDEX($C8:$N8,1,MATCH(AT$5,$C$5:$N$5,0)))/SUM($O8:INDEX($O8:$Z8,1,MATCH(AT$5,$O$5:$Z$5,0))) -> 0.95753425
B9: Total | C9: =INDEX('Order Accepted'!$F26:$N26,MATCH(C$5,'Order Accepted'!$F25:$N25,0)) -> 3680000 | D9: =INDEX('Order Accepted'!$F26:$N26,MATCH(D$5,'Order Accepted'!$F25:$N25,0)) -> 3980000 | E9: =INDEX('Order Accepted'!$F26:$N26,MATCH(E$5,'Order Accepted'!$F25:$N25,0)) -> 4290000 | F9: =INDEX('Order Accepted'!$F26:$N26,MATCH(F$5,'Order Accepted'!$F25:$N25,0)) -> 4520000 | G9: =INDEX('Order Accepted'!$F26:$N26,MATCH(G$5,'Order Accepted'!$F25:$N25,0)) -> 4290000 | H9: =INDEX('Order Accepted'!$F26:$N26,MATCH(H$5,'Order Accepted'!$F25:$N25,0)) -> 4790000 | I9: =INDEX('Order Accepted'!$F26:$N26,MATCH(I$5,'Order Accepted'!$F25:$N25,0)) -> 4620000 | J9: =INDEX('Order Accepted'!$F26:$N26,MATCH(J$5,'Order Accepted'!$F25:$N25,0)) -> 5010000 | O9: =INDEX(OA_Target!$F26:$N26,MATCH(O$5,OA_Target!$F25:$N25,0)) -> 3350000 | P9: =INDEX(OA_Target!$F26:$N26,MATCH(P$5,OA_Target!$F25:$N25,0)) -> 4720000 | Q9: =INDEX(OA_Target!$F26:$N26,MATCH(Q$5,OA_Target!$F25:$N25,0)) -> 4760000 | R9: =INDEX(OA_Target!$F26:$N26,MATCH(R$5,OA_Target!$F25:$N25,0)) -> 5300000 | S9: =INDEX(OA_Target!$F26:$N26,MATCH(S$5,OA_Target!$F25:$N25,0)) -> 4700000 | T9: =INDEX(OA_Target!$F26:$N26,MATCH(T$5,OA_Target!$F25:$N25,0)) -> 5100000 | U9: =INDEX(OA_Target!$F26:$N26,MATCH(U$5,OA_Target!$F25:$N25,0)) -> 5200000 | V9: =INDEX(OA_Target!$F26:$N26,MATCH(V$5,OA_Target!$F25:$N25,0)) -> 4900000 | AA9: =C9/O9 -> 1.0985075 | AB9: =D9/P9 -> 0.84322034 | AC9: =E9/Q9 -> 0.9012605 | AD9: =F9/R9 -> 0.85283019 | AE9: =G9/S9 -> 0.91276596 | AF9: =H9/T9 -> 0.93921569 | AG9: =I9/U9 -> 0.88846154 | AH9: =J9/V9 -> 1.022449 | AM9: =SUM($C9:INDEX($C9:$N9,1,MATCH(AM$5,$C$5:$N$5,0)))/SUM($O9:INDEX($O9:$Z9,1,MATCH(AM$5,$O$5:$Z$5,0))) -> 1.0985075 | AN9: =SUM($C9:INDEX($C9:$N9,1,MATCH(AN$5,$C$5:$N$5,0)))/SUM($O9:INDEX($O9:$Z9,1,MATCH(AN$5,$O$5:$Z$5,0))) -> 0.94919455 | AO9: =SUM($C9:INDEX($C9:$N9,1,MATCH(AO$5,$C$5:$N$5,0)))/SUM($O9:INDEX($O9:$Z9,1,MATCH(AO$5,$O$5:$Z$5,0))) -> 0.93141076 | AP9: =SUM($C9:INDEX($C9:$N9,1,MATCH(AP$5,$C$5:$N$5,0)))/SUM($O9:INDEX($O9:$Z9,1,MATCH(AP$5,$O$5:$Z$5,0))) -> 0.90843905 | AQ9: =SUM($C9:INDEX($C9:$N9,1,MATCH(AQ$5,$C$5:$N$5,0)))/SUM($O9:INDEX($O9:$Z9,1,MATCH(AQ$5,$O$5:$Z$5,0))) -> 0.90932983 | AR9: =SUM($C9:INDEX($C9:$N9,1,MATCH(AR$5,$C$5:$N$5,0)))/SUM($O9:INDEX($O9:$Z9,1,MATCH(AR$5,$O$5:$Z$5,0))) -> 0.91478697 | AS9: =SUM($C9:INDEX($C9:$N9,1,MATCH(AS$5,$C$5:$N$5,0)))/SUM($O9:INDEX($O9:$Z9,1,MATCH(AS$5,$O$5:$Z$5,0))) -> 0.910655 | AT9: =SUM($C9:INDEX($C9:$N9,1,MATCH(AT$5,$C$5:$N$5,0)))/SUM($O9:INDEX($O9:$Z9,1,MATCH(AT$5,$O$5:$Z$5,0))) -> 0.92505916
B12: Order Delivered
B14: LOP | C14: Value | O14: Target | AA14: Value vs Target | AM14: Cumulative
B15: Product | C15: ='Order Delivered'!F$4 -> Jan | D15: ='Order Delivered'!G$4 -> Feb | E15: ='Order Delivered'!H$4 -> Mar | F15: ='Order Delivered'!I$4 -> Apr | G15: ='Order Delivered'!J$4 -> May | H15: ='Order Delivered'!K$4 -> Jun | I15: ='Order Delivered'!L$4 -> Jul | J15: ='Order Delivered'!M$4 -> Aug | O15: =OD_Target!F4 -> Jan | P15: =OD_Target!G4 -> Feb | Q15: =OD_Target!H4 -> Mar | R15: =OD_Target!I4 -> Apr | S15: =OD_Target!J4 -> May | T15: =OD_Target!K4 -> Jun | U15: =OD_Target!L4 -> Jul | V15: =OD_Target!M4 -> Aug | AA15: Jan | AB15: Feb | AC15: Mar | AD15: Apr | AE15: May | AF15: Jun | AG15: Jul | AH15: Aug | AI15: Sep | AJ15: Oct | AK15: Nov | AL15: Dec | AM15: Jan | AN15: Feb | AO15: Mar | AP15: Apr | AQ15: May | AR15: Jun | AS15: Jul | AT15: Aug | AU15: Sep | AV15: Oct | AW15: Nov | AX15: Dec
B16: Product A | C16: =INDEX('Order Delivered'!$F$5:$N$5, MATCH(C$15,'Order Delivered'!$F$4:$N$4,0)) -> 1138000 | D16: =INDEX('Order Delivered'!$F$5:$N$5, MATCH(D$15,'Order Delivered'!$F$4:$N$4,0)) -> 1214000 | E16: =INDEX('Order Delivered'!$F$5:$N$5, MATCH(E$15,'Order Delivered'!$F$4:$N$4,0)) -> 1311000 | F16: =INDEX('Order Delivered'!$F$5:$N$5, MATCH(F$15,'Order Delivered'!$F$4:$N$4,0)) -> 1425000 | G16: =INDEX('Order Delivered'!$F$5:$N$5, MATCH(G$15,'Order Delivered'!$F$4:$N$4,0)) -> 1316000 | H16: =INDEX('Order Delivered'!$F$5:$N$5, MATCH(H$15,'Order Delivered'!$F$4:$N$4,0)) -> 1504000 | I16: =INDEX('Order Delivered'!$F$5:$N$5, MATCH(I$15,'Order Delivered'!$F$4:$N$4,0)) -> 1432000 | J16: =INDEX('Order Delivered'!$F$5:$N$5, MATCH(J$15,'Order Delivered'!$F$4:$N$4,0)) -> 1596000 | O16: =INDEX(OD_Target!$F$5:$N$5, MATCH(O$15,OD_Target!$F$4:$N$4,0)) -> 1200000 | P16: =INDEX(OD_Target!$F$5:$N$5, MATCH(P$15,OD_Target!$F$4:$N$4,0)) -> 1300000 | Q16: =INDEX(OD_Target!$F$5:$N$5, MATCH(Q$15,OD_Target!$F$4:$N$4,0)) -> 1300000 | R16: =INDEX(OD_Target!$F$5:$N$5, MATCH(R$15,OD_Target!$F$4:$N$4,0)) -> 1500000 | S16: =INDEX(OD_Target!$F$5:$N$5, MATCH(S$15,OD_Target!$F$4:$N$4,0)) -> 1300000 | T16: =INDEX(OD_Target!$F$5:$N$5, MATCH(T$15,OD_Target!$F$4:$N$4,0)) -> 1600000 | U16: =INDEX(OD_Target!$F$5:$N$5, MATCH(U$15,OD_Target!$F$4:$N$4,0)) -> 1800000 | V16: =INDEX(OD_Target!$F$5:$N$5, MATCH(V$15,OD_Target!$F$4:$N$4,0)) -> 1600000 | AA16: =C16/O16 -> 0.94833333 | AB16: =D16/P16 -> 0.93384615 | AC16: =E16/Q16 -> 1.0084615 | AD16: =F16/R16 -> 0.95 | AE16: =G16/S16 -> 1.0123077 | AF16: =H16/T16 -> 0.94 | AG16: =I16/U16 -> 0.79555556 | AH16: =J16/V16 -> 0.9975 | AM16: =SUM($C16:INDEX($C16:$N16,1,MATCH(AM$5,$C$5:$N$5,0)))/SUM($O16:INDEX($O16:$Z16,1,MATCH(AM$5,$O$5:$Z$5,0))) -> 0.94833333 | AN16: =SUM($C16:INDEX($C16:$N16,1,MATCH(AN$5,$C$5:$N$5,0)))/SUM($O16:INDEX($O16:$Z16,1,MATCH(AN$5,$O$5:$Z$5,0))) -> 0.9408 | AO16: =SUM($C16:INDEX($C16:$N16,1,MATCH(AO$5,$C$5:$N$5,0)))/SUM($O16:INDEX($O16:$Z16,1,MATCH(AO$5,$O$5:$Z$5,0))) -> 0.96394737 | AP16: =SUM($C16:INDEX($C16:$N16,1,MATCH(AP$5,$C$5:$N$5,0)))/SUM($O16:INDEX($O16:$Z16,1,MATCH(AP$5,$O$5:$Z$5,0))) -> 0.96 | AQ16: =SUM($C16:INDEX($C16:$N16,1,MATCH(AQ$5,$C$5:$N$5,0)))/SUM($O16:INDEX($O16:$Z16,1,MATCH(AQ$5,$O$5:$Z$5,0))) -> 0.97030303 | AR16: =SUM($C16:INDEX($C16:$N16,1,MATCH(AR$5,$C$5:$N$5,0)))/SUM($O16:INDEX($O16:$Z16,1,MATCH(AR$5,$O$5:$Z$5,0))) -> 0.96439024 | AS16: =SUM($C16:INDEX($C16:$N16,1,MATCH(AS$5,$C$5:$N$5,0)))/SUM($O16:INDEX($O16:$Z16,1,MATCH(AS$5,$O$5:$Z$5,0))) -> 0.934 | AT16: =SUM($C16:INDEX($C16:$N16,1,MATCH(AT$5,$C$5:$N$5,0)))/SUM($O16:INDEX($O16:$Z16,1,MATCH(AT$5,$O$5:$Z$5,0))) -> 0.94275862
B17: Product B | C17: =INDEX('Order Delivered'!$F$12:$N$12, MATCH(C$15,'Order Delivered'!$F$11:$N$11,0)) -> 911000 | D17: =INDEX('Order Delivered'!$F$12:$N$12, MATCH(D$15,'Order Delivered'!$F$11:$N$11,0)) -> 1015000 | E17: =INDEX('Order Delivered'!$F$12:$N$12, MATCH(E$15,'Order Delivered'!$F$11:$N$11,0)) -> 1067000 | F17: =INDEX('Order Delivered'!$F$12:$N$12, MATCH(F$15,'Order Delivered'!$F$11:$N$11,0)) -> 1125000 | G17: =INDEX('Order Delivered'!$F$12:$N$12, MATCH(G$15,'Order Delivered'!$F$11:$N$11,0)) -> 1112000 | H17: =INDEX('Order Delivered'!$F$12:$N$12, MATCH(H$15,'Order Delivered'!$F$11:$N$11,0)) -> 1178000 | I17: =INDEX('Order Delivered'!$F$12:$N$12, MATCH(I$15,'Order Delivered'!$F$11:$N$11,0)) -> 1166000 | J17: =INDEX('Order Delivered'!$F$12:$N$12, MATCH(J$15,'Order Delivered'!$F$11:$N$11,0)) -> 1256000 | O17: =INDEX(OD_Target!$F$12:$N$12, MATCH(O$15,OD_Target!$F$11:$N$11,0)) -> 1000000 | P17: =INDEX(OD_Target!$F$12:$N$12, MATCH(P$15,OD_Target!$F$11:$N$11,0)) -> 1200000 | Q17: =INDEX(OD_Target!$F$12:$N$12, MATCH(Q$15,OD_Target!$F$11:$N$11,0)) -> 1100000 | R17: =INDEX(OD_Target!$F$12:$N$12, MATCH(R$15,OD_Target!$F$11:$N$11,0)) -> 1200000 | S17: =INDEX(OD_Target!$F$12:$N$12, MATCH(S$15,OD_Target!$F$11:$N$11,0)) -> 1200000 | T17: =INDEX(OD_Target!$F$12:$N$12, MATCH(T$15,OD_Target!$F$11:$N$11,0)) -> 1200000 | U17: =INDEX(OD_Target!$F$12:$N$12, MATCH(U$15,OD_Target!$F$11:$N$11,0)) -> 1200000 | V17: =INDEX(OD_Target!$F$12:$N$12, MATCH(V$15,OD_Target!$F$11:$N$11,0)) -> 1200000 | AA17: =C17/O17 -> 0.911 | AB17: =D17/P17 -> 0.84583333 | AC17: =E17/Q17 -> 0.97 | AD17: =F17/R17 -> 0.9375 | AE17: =G17/S17 -> 0.92666667 | AF17: =H17/T17 -> 0.98166667 | AG17: =I17/U17 -> 0.97166667 | AH17: =J17/V17 -> 1.0466667 | AM17: =SUM($C17:INDEX($C17:$N17,1,MATCH(AM$5,$C$5:$N$5,0)))/SUM($O17:INDEX($O17:$Z17,1,MATCH(AM$5,$O$5:$Z$5,0))) -> 0.911 | AN17: =SUM($C17:INDEX($C17:$N17,1,MATCH(AN$5,$C$5:$N$5,0)))/SUM($O17:INDEX($O17:$Z17,1,MATCH(AN$5,$O$5:$Z$5,0))) -> 0.87545455 | AO17: =SUM($C17:INDEX($C17:$N17,1,MATCH(AO$5,$C$5:$N$5,0)))/SUM($O17:INDEX($O17:$Z17,1,MATCH(AO$5,$O$5:$Z$5,0))) -> 0.9069697 | AP17: =SUM($C17:INDEX($C17:$N17,1,MATCH(AP$5,$C$5:$N$5,0)))/SUM($O17:INDEX($O17:$Z17,1,MATCH(AP$5,$O$5:$Z$5,0))) -> 0.91511111 | AQ17: =SUM($C17:INDEX($C17:$N17,1,MATCH(AQ$5,$C$5:$N$5,0)))/SUM($O17:INDEX($O17:$Z17,1,MATCH(AQ$5,$O$5:$Z$5,0))) -> 0.91754386 | AR17: =SUM($C17:INDEX($C17:$N17,1,MATCH(AR$5,$C$5:$N$5,0)))/SUM($O17:INDEX($O17:$Z17,1,MATCH(AR$5,$O$5:$Z$5,0))) -> 0.92869565 | AS17: =SUM($C17:INDEX($C17:$N17,1,MATCH(AS$5,$C$5:$N$5,0)))/SUM($O17:INDEX($O17:$Z17,1,MATCH(AS$5,$O$5:$Z$5,0))) -> 0.93506173 | AT17: =SUM($C17:INDEX($C17:$N17,1,MATCH(AT$5,$C$5:$N$5,0)))/SUM($O17:INDEX($O17:$Z17,1,MATCH(AT$5,$O$5:$Z$5,0))) -> 0.94946237
B18: Product C | C18: =INDEX('Order Delivered'!$F$19:$N$19, MATCH(C$15,'Order Delivered'!$F$18:$N$18,0)) -> 1305000 | D18: =INDEX('Order Delivered'!$F$19:$N$19, MATCH(D$15,'Order Delivered'!$F$18:$N$18,0)) -> 1438000 | E18: =INDEX('Order Delivered'!$F$19:$N$19, MATCH(E$15,'Order Delivered'!$F$18:$N$18,0)) -> 1617000 | F18: =INDEX('Order Delivered'!$F$19:$N$19, MATCH(F$15,'Order Delivered'!$F$18:$N$18,0)) -> 1665000 | G18: =INDEX('Order Delivered'!$F$19:$N$19, MATCH(G$15,'Order Delivered'!$F$18:$N$18,0)) -> 1572000 | H18: =INDEX('Order Delivered'!$F$19:$N$19, MATCH(H$15,'Order Delivered'!$F$18:$N$18,0)) -> 1814000 | I18: =INDEX('Order Delivered'!$F$19:$N$19, MATCH(I$15,'Order Delivered'!$F$18:$N$18,0)) -> 1693000 | J18: =INDEX('Order Delivered'!$F$19:$N$19, MATCH(J$15,'Order Delivered'!$F$18:$N$18,0)) -> 1861000 | O18: =INDEX(OD_Target!$F$19:$N$19, MATCH(O$15,OD_Target!$F$18:$N$18,0)) -> 1300000 | P18: =INDEX(OD_Target!$F$19:$N$19, MATCH(P$15,OD_Target!$F$18:$N$18,0)) -> 1400000 | Q18: =INDEX(OD_Target!$F$19:$N$19, MATCH(Q$15,OD_Target!$F$18:$N$18,0)) -> 1600000 | R18: =INDEX(OD_Target!$F$19:$N$19, MATCH(R$15,OD_Target!$F$18:$N$18,0)) -> 1600000 | S18: =INDEX(OD_Target!$F$19:$N$19, MATCH(S$15,OD_Target!$F$18:$N$18,0)) -> 1500000 | T18: =INDEX(OD_Target!$F$19:$N$19, MATCH(T$15,OD_Target!$F$18:$N$18,0)) -> 2000000 | U18: =INDEX(OD_Target!$F$19:$N$19, MATCH(U$15,OD_Target!$F$18:$N$18,0)) -> 1800000 | V18: =INDEX(OD_Target!$F$19:$N$19, MATCH(V$15,OD_Target!$F$18:$N$18,0)) -> 1800000 | AA18: =C18/O18 -> 1.0038462 | AB18: =D18/P18 -> 1.0271429 | AC18: =E18/Q18 -> 1.010625 | AD18: =F18/R18 -> 1.040625 | AE18: =G18/S18 -> 1.048 | AF18: =H18/T18 -> 0.907 | AG18: =I18/U18 -> 0.94055556 | AH18: =J18/V18 -> 1.0338889 | AM18: =SUM($C18:INDEX($C18:$N18,1,MATCH(AM$5,$C$5:$N$5,0)))/SUM($O18:INDEX($O18:$Z18,1,MATCH(AM$5,$O$5:$Z$5,0))) -> 1.0038462 | AN18: =SUM($C18:INDEX($C18:$N18,1,MATCH(AN$5,$C$5:$N$5,0)))/SUM($O18:INDEX($O18:$Z18,1,MATCH(AN$5,$O$5:$Z$5,0))) -> 1.0159259 | AO18: =SUM($C18:INDEX($C18:$N18,1,MATCH(AO$5,$C$5:$N$5,0)))/SUM($O18:INDEX($O18:$Z18,1,MATCH(AO$5,$O$5:$Z$5,0))) -> 1.0139535 | AP18: =SUM($C18:INDEX($C18:$N18,1,MATCH(AP$5,$C$5:$N$5,0)))/SUM($O18:INDEX($O18:$Z18,1,MATCH(AP$5,$O$5:$Z$5,0))) -> 1.0211864 | AQ18: =SUM($C18:INDEX($C18:$N18,1,MATCH(AQ$5,$C$5:$N$5,0)))/SUM($O18:INDEX($O18:$Z18,1,MATCH(AQ$5,$O$5:$Z$5,0))) -> 1.0266216 | AR18: =SUM($C18:INDEX($C18:$N18,1,MATCH(AR$5,$C$5:$N$5,0)))/SUM($O18:INDEX($O18:$Z18,1,MATCH(AR$5,$O$5:$Z$5,0))) -> 1.0011702 | AS18: =SUM($C18:INDEX($C18:$N18,1,MATCH(AS$5,$C$5:$N$5,0)))/SUM($O18:INDEX($O18:$Z18,1,MATCH(AS$5,$O$5:$Z$5,0))) -> 0.99142857 | AT18: =SUM($C18:INDEX($C18:$N18,1,MATCH(AT$5,$C$5:$N$5,0)))/SUM($O18:INDEX($O18:$Z18,1,MATCH(AT$5,$O$5:$Z$5,0))) -> 0.99730769
B19: Total | C19: =INDEX('Order Delivered'!$F$26:$N$26, MATCH(C$15,'Order Delivered'!$F$25:$N$25,0)) -> 3354000 | D19: =INDEX('Order Delivered'!$F$26:$N$26, MATCH(D$15,'Order Delivered'!$F$25:$N$25,0)) -> 3667000 | E19: =INDEX('Order Delivered'!$F$26:$N$26, MATCH(E$15,'Order Delivered'!$F$25:$N$25,0)) -> 3995000 | F19: =INDEX('Order Delivered'!$F$26:$N$26, MATCH(F$15,'Order Delivered'!$F$25:$N$25,0)) -> 4215000 | G19: =INDEX('Order Delivered'!$F$26:$N$26, MATCH(G$15,'Order Delivered'!$F$25:$N$25,0)) -> 4000000 | H19: =INDEX('Order Delivered'!$F$26:$N$26, MATCH(H$15,'Order Delivered'!$F$25:$N$25,0)) -> 4496000 | I19: =INDEX('Order Delivered'!$F$26:$N$26, MATCH(I$15,'Order Delivered'!$F$25:$N$25,0)) -> 4291000 | J19: =INDEX('Order Delivered'!$F$26:$N$26, MATCH(J$15,'Order Delivered'!$F$25:$N$25,0)) -> 4713000 | O19: =INDEX(OD_Target!$F$26:$N$26, MATCH(O$15,OD_Target!$F$25:$N$25,0)) -> 3500000 | P19: =INDEX(OD_Target!$F$26:$N$26, MATCH(P$15,OD_Target!$F$25:$N$25,0)) -> 3900000 | Q19: =INDEX(OD_Target!$F$26:$N$26, MATCH(Q$15,OD_Target!$F$25:$N$25,0)) -> 4000000 | R19: =INDEX(OD_Target!$F$26:$N$26, MATCH(R$15,OD_Target!$F$25:$N$25,0)) -> 4300000 | S19: =INDEX(OD_Target!$F$26:$N$26, MATCH(S$15,OD_Target!$F$25:$N$25,0)) -> 4000000 | T19: =INDEX(OD_Target!$F$26:$N$26, MATCH(T$15,OD_Target!$F$25:$N$25,0)) -> 4800000 | U19: =INDEX(OD_Target!$F$26:$N$26, MATCH(U$15,OD_Target!$F$25:$N$25,0)) -> 4800000 | V19: =INDEX(OD_Target!$F$26:$N$26, MATCH(V$15,OD_Target!$F$25:$N$25,0)) -> 4600000 | AA19: =C19/O19 -> 0.95828571 | AB19: =D19/P19 -> 0.94025641 | AC19: =E19/Q19 -> 0.99875 | AD19: =F19/R19 -> 0.98023256 | AE19: =G19/S19 -> 1 | AF19: =H19/T19 -> 0.93666667 | AG19: =I19/U19 -> 0.89395833 | AH19: =J19/V19 -> 1.0245652 | AM19: =SUM($C19:INDEX($C19:$N19,1,MATCH(AM$5,$C$5:$N$5,0)))/SUM($O19:INDEX($O19:$Z19,1,MATCH(AM$5,$O$5:$Z$5,0))) -> 0.95828571 | AN19: =SUM($C19:INDEX($C19:$N19,1,MATCH(AN$5,$C$5:$N$5,0)))/SUM($O19:INDEX($O19:$Z19,1,MATCH(AN$5,$O$5:$Z$5,0))) -> 0.94878378 | AO19: =SUM($C19:INDEX($C19:$N19,1,MATCH(AO$5,$C$5:$N$5,0)))/SUM($O19:INDEX($O19:$Z19,1,MATCH(AO$5,$O$5:$Z$5,0))) -> 0.96631579 | AP19: =SUM($C19:INDEX($C19:$N19,1,MATCH(AP$5,$C$5:$N$5,0)))/SUM($O19:INDEX($O19:$Z19,1,MATCH(AP$5,$O$5:$Z$5,0))) -> 0.97012739 | AQ19: =SUM($C19:INDEX($C19:$N19,1,MATCH(AQ$5,$C$5:$N$5,0)))/SUM($O19:INDEX($O19:$Z19,1,MATCH(AQ$5,$O$5:$Z$5,0))) -> 0.97619289 | AR19: =SUM($C19:INDEX($C19:$N19,1,MATCH(AR$5,$C$5:$N$5,0)))/SUM($O19:INDEX($O19:$Z19,1,MATCH(AR$5,$O$5:$Z$5,0))) -> 0.96844898 | AS19: =SUM($C19:INDEX($C19:$N19,1,MATCH(AS$5,$C$5:$N$5,0)))/SUM($O19:INDEX($O19:$Z19,1,MATCH(AS$5,$O$5:$Z$5,0))) -> 0.95624573 | AT19: =SUM($C19:INDEX($C19:$N19,1,MATCH(AT$5,$C$5:$N$5,0)))/SUM($O19:INDEX($O19:$Z19,1,MATCH(AT$5,$O$5:$Z$5,0))) -> 0.96551622
B22: Churn
B24: LOP | C24: Value | O24: Target | AA24: Value vs Target | AM24: Cumulative
B25: Product | C25: =Churn!F4 -> Jan | D25: =Churn!G4 -> Feb | E25: =Churn!H4 -> Mar | F25: =Churn!I4 -> Apr | G25: =Churn!J4 -> May | H25: =Churn!K4 -> Jun | I25: =Churn!L4 -> Jul | J25: =Churn!M4 -> Aug | O25: ='Churn_Target'!F4 -> Jan | P25: ='Churn_Target'!G4 -> Feb | Q25: ='Churn_Target'!H4 -> Mar | R25: ='Churn_Target'!I4 -> Apr | S25: ='Churn_Target'!J4 -> May | T25: ='Churn_Target'!K4 -> Jun | U25: ='Churn_Target'!L4 -> Jul | V25: ='Churn_Target'!M4 -> Aug | AA25: Jan | AB25: Feb | AC25: Mar | AD25: Apr | AE25: May | AF25: Jun | AG25: Jul | AH25: Aug | AI25: Sep | AJ25: Oct | AK25: Nov | AL25: Dec | AM25: Jan | AN25: Feb | AO25: Mar | AP25: Apr | AQ25: May | AR25: Jun | AS25: Jul | AT25: Aug | AU25: Sep | AV25: Oct | AW25: Nov | AX25: Dec
